Workbook

Sheet Retail_Dataset
A1: Order ID | B1: Region | C1: Country | D1: Category | E1: Sales Channel | F1: Order Priority | G1: Order Date | H1: Units Sold | I1: Unit Price | J1: Unit Cost | K1: Total Revenue | L1: Profit
A2: ORD0001 | B2: East | C2: Germany | D2: Beverages | E2: Online | F2: High | G2: 44927 | H2: 235 | I2: 152.92 | J2: 153.6 | K2: =H2*I2 -> 35936.2 | L2: =K2-J2 -> 35782.6
A3: ORD0002 | B3: West | C3: India | D3: Food | E3: Online | F3: Low | G3: 44928 | H3: 341 | I3: 467.92 | J3: 139.84 | K3: =H3*I3 -> 159560.72 | L3: =K3-J3 -> 159420.88
A4: ORD0003 | B4: North | C4: India | D4: Clothing | E4: Offline | F4: High | G4: 44929 | H4: 179 | I4: 473.94 | J4: 97.14 | K4: =H4*I4 -> 84835.26 | L4: =K4-J4 -> 84738.12
A5: ORD0004 | B5: East | C5: USA | D5: Furniture | E5: Offline | F5: Medium | G5: 44930 | H5: 18 | I5: 314.53 | J5: 204.87 | K5: =H5*I5 -> 5661.54 | L5: =K5-J5 -> 5456.67
A6: ORD0005 | B6: East | C6: India | D6: Furniture | E6: Offline | F6: Medium | G6: 44931 | H6: 472 | I6: 392.79 | J6: 330.46 | K6: =H6*I6 -> 185396.88 | L6: =K6-J6 -> 185066.42
A7: ORD0006 | B7: West | C7: UK | D7: Clothing | E7: Online | F7: High | G7: 44932 | H7: 49 | I7: 308.07 | J7: 113.32 | K7: =H7*I7 -> 15095.43 | L7: =K7-J7 -> 14982.11
A8: ORD0007 | B8: North | C8: Germany | D8: Clothing | E8: Online | F8: Low | G8: 44933 | H8: 34 | I8: 244.78 | J8: 377.07 | K8: =H8*I8 -> 8322.52 | L8: =K8-J8 -> 7945.45
A9: ORD0008 | B9: North | C9: India | D9: Beverages | E9: Online | F9: High | G9: 44934 | H9: 270 | I9: 332.11 | J9: 349.59 | K9: =H9*I9 -> 89669.7 | L9: =K9-J9 -> 89320.11
A10: ORD0009 | B10: East | C10: India | D10: Beverages | E10: Online | F10: Low | G10: 44935 | H10: 404 | I10: 278.74 | J10: 66.38 | K10: =H10*I10 -> 112610.96 | L10: =K10-J10 -> 112544.58
A11: ORD0010 | B11: North | C11: USA | D11: Furniture | E11: Online | F11: Medium | G11: 44936 | H11: 452 | I11: 300.75 | J11: 314.94 | K11: =H11*I11 -> 135939 | L11: =K11-J11 -> 135624.06
A12: ORD0011 | B12: East | C12: USA | D12: Food | E12: Online | F12: Low | G12: 44937 | H12: 235 | I12: 393 | J12: 230.69 | K12: =H12*I12 -> 92355 | L12: =K12-J12 -> 92124.31
A13: ORD0012 | B13: East | C13: UK | D13: Furniture | E13: Offline | F13: Medium | G13: 44938 | H13: 481 | I13: 243.05 | J13: 227.5 | K13: =H13*I13 -> 116907.05 | L13: =K13-J13 -> 116679.55
... A25: ORD0024 | B25: West | C25: UK | D25: Electronics | E25: Offline | F25: Medium | G25: 44950 | H25: 325 | I25: 436.56 | J25: 130.37 | K25: =H25*I25 -> 141882 | L25: =K25-J25 -> 141751.63
A26: ORD0025 | B26: West | C26: India | E26: Offline | F26: Medium | G26: 44951 | H26: 185 | I26: 219.66 | J26: 11.11 | K26: =H26*I26 -> 40637.1 | L26: =K26-J26 -> 40625.99
A27: ORD0026 | B27: South | C27: India | D27: Beverages | E27: Offline | F27: High | G27: 44952 | H27: 470 | I27: 26.61 | J27: 63.21 | K27: =H27*I27 -> 12506.7 | L27: =K27-J27 -> 12443.49
A28: ORD0027 | B28: South | C28: UK | D28: Furniture | E28: Online | F28: Medium | G28: 44953 | H28: 293 | I28: 85.03 | J28: 91 | K28: =H28*I28 -> 24913.79 | L28: =K28-J28 -> 24822.79
A29: ORD0028 | B29: South | C29: UK | D29: Food | E29: Online | F29: Medium | G29: 44954 | H29: 462 | J29: 383.01 | K29: =H29*I29 -> 0 | L29: =K29-J29 -> -383.01
A30: ORD0029 | B30: West | C30: UK | D30: Beverages | E30: Offline | F30: Low | G30: 44955 | H30: 470 | I30: 328.37 | J30: 230.07 | K30: =H30*I30 -> 154333.9 | L30: =K30-J30 -> 154103.83
A31: ORD0030 | B31: West | C31: Germany | D31: Beverages | E31: Online | F31: Medium | G31: 44956 | H31: 90 | I31: 169.5 | J31: 373.23 | K31: =H31*I31 -> 15255 | L31: =K31-J31 -> 14881.77
A32: ORD0031 | B32: West | C32: India | D32: Beverages | E32: Online | F32: Low | G32: 44957 | H32: 123 | I32: 273.53 | J32: 230.92 | K32: =H32*I32 -> 33644.19 | L32: =K32-J32 -> 33413.27
A33: ORD0032 | B33: North | C33: Germany | D33: Beverages | E33: Online | F33: High | G33: 44958 | H33: 49 | I33: 249.17 | J33: 192.78 | K33: =H33*I33 -> 12209.33 | L33: =K33-J33 -> 12016.55
A34: ORD0033 | B34: West | C34: UK | D34: Beverages | E34: Online | F34: Medium | G34: 44959 | H34: 310 | I34: 45.36 | J34: 126.86 | K34: =H34*I34 -> 14061.6 | L34: =K34-J34 -> 13934.74
A35: ORD0034 | B35: South | C35: India | D35: Clothing | E35: Online | F35: Low | G35: 44960 | H35: 233 | I35: 204.61 | J35: 243.34 | K35: =H35*I35 -> 47674.13 | L35: =K35-J35 -> 47430.79
A36: ORD0035 | B36: South | C36: Germany | D36: Food | E36: Online | F36: High | G36: 44961 | H36: 327 | I36: 114.18 | J36: 57.4 | K36: =H36*I36 -> 37336.86 | L36: =K36-J36 -> 37279.46
A37: ORD0036 | B37: North | C37: Germany | D37: Beverages | E37: Online | F37: Medium | G37: 44962 | H37: 358 | I37: 212.11 | J37: 359.51 | K37: =H37*I37 -> 75935.38 | L37: =K37-J37 -> 75575.87
A38: ORD0037 | B38: West | C38: UK | D38: Food | E38: Online | F38: High | G38: 44963 | H38: 124 | J38: 332.07 | K38: =H38*I38 -> 0 | L38: =K38-J38 -> -332.07
A39: ORD0038 | B39: North | C39: India | D39: Clothing | E39: Online | F39: Medium | G39: 44964 | H39: 195 | I39: 421.02 | J39: 128.38 | K39: =H39*I39 -> 82098.9 | L39: =K39-J39 -> 81970.52
A40: ORD0039 | B40: North | C40: UK | D40: Clothing | E40: Online | F40: High | G40: 44965 | I40: 91.23 | J40: 381.21 | K40: =H40*I40 -> 0 | L40: =K40-J40 -> -381.21
A41: ORD0040 | B41: East | C41: India | D41: Food | E41: Offline | F41: High | G41: 44966 | H41: 65 | I41: 480.59 | J41: 330.43 | K41: =H41*I41 -> 31238.35 | L41: =K41-J41 -> 30907.92
A42: ORD0041 | B42: East | C42: Australia | D42: Electronics | E42: Offline | F42: Low | G42: 44967 | H42: 49 | I42: 210.87 | J42: 267.19 | K42: =H42*I42 -> 10332.63 | L42: =K42-J42 -> 10065.44
A43: ORD0042 | B43: East | C43: USA | D43: Furniture | E43: Online | F43: High | G43: 44968 | H43: 363 | I43: 423.89 | J43: 50.46 | K43: =H43*I43 -> 153872.07 | L43: =K43-J43 -> 153821.61
A44: ORD0043 | B44: South | C44: USA | D44: Electronics | E44: Offline | F44: Medium | G44: 44969 | H44: 49 | I44: 316.24 | J44: 192.34 | K44: =H44*I44 -> 15495.76 | L44: =K44-J44 -> 15303.42
A45: ORD0044 | B45: West | C45: USA | D45: Electronics | E45: Offline | F45: Medium | G45: 44970 | H45: 356 | I45: 369 | J45: 203.43 | K45: =H45*I45 -> 131364 | L45: =K45-J45 -> 131160.57
A46: ORD0045 | B46: West | C46: UK | D46: Electronics | E46: Online | F46: Low | G46: 44971 | H46: 470 | J46: 94.56 | K46: =H46*I46 -> 0 | L46: =K46-J46 -> -94.56
A47: ORD0046 | B47: West | C47: Australia | D47: Beverages | E47: Online | F47: Medium | G47: 44972 | H47: 246 | I47: 254.9 | J47: 33.83 | K47: =H47*I47 -> 62705.4 | L47: =K47-J47 -> 62671.57
A48: ORD0047 | B48: West | C48: India | D48: Clothing | E48: Online | F48: Medium | G48: 44973 | H48: 298 | I48: 273.93 | J48: 311.14 | K48: =H48*I48 -> 81631.14 | L48: =K48-J48 -> 81320
A49: ORD0048 | B49: East | C49: Germany | D49: Electronics | E49: Offline | F49: Medium | G49: 44974 | H49: 271 | I49: 259.43 | J49: 50.57 | K49: =H49*I49 -> 70305.53 | L49: =K49-J49 -> 70254.96
A50: ORD0049 | B50: South | C50: India | D50: Clothing | E50: Offline | F50: High | G50: 44975 | H50: 225 | I50: 296.09 | J50: 238.53 | K50: =H50*I50 -> 66620.25 | L50: =K50-J50 -> 66381.72
A51: ORD0050 | B51: West | C51: Germany | D51: Food | E51: Online | F51: High | G51: 44976 | H51: 156 | I51: 19.55 | J51: 374.71 | K51: =H51*I51 -> 3049.8 | L51: =K51-J51 -> 2675.09
...

Sheet QUES1
B2: Q1. Use Copilot to identify and summarize missing values in the dataset.
B4: Copilot Prompt - : | D4: Identify all columns with missing values and provide a summary of the missing data.
B6: Column Name | D6: Missing Values
B7: Region | D7: =COUNTBLANK(Retail_Dataset!B2:B351) -> 0
B8: Category | D8: =COUNTBLANK(Retail_Dataset!D2:D351) -> 10
B9: Units Sold | D9: =COUNTBLANK(Retail_Dataset!H2:H351) -> 10
B10: Unit Price | D10: =COUNTBLANK(Retail_Dataset!I2:I351) -> 10
B13: Copilot response -: | D13: Copilot analyzed the dataset and identified missing values in multiple columns. The Region and Category columns contained missing
D14: categorical values, while Units Sold and Unit Price had missing numerical entries.
D15: These missing values may affect calculations and analysis and therefore need to be addressed before further data processing.
B18: Formula Used -: =COUNTBLANK(range)

Sheet QUES2
C2: Ques 2 - | D2: Missing Value In Region .
C4: Copilot Prompt :- | E4: "Fill the missing values in the 'Region' column using the most frequent value."
C6: Solution :- | E6: The Region column contained missing values.
E7: Copilot identified the most frequently occurring region in the dataset and used it to fill the missing entries.
E8: This method ensures consistency in the dataset and avoids introducing random values.

Sheet QUES3
A2: Ques 3 :- | B2: Missing Values in Units Sold & Unit Price
A4: Copilot Prompt :- | C4: Replace missing values in 'Units Sold' and 'Unit Price' using the average (mean) of their respective columns.
A6: Solution :- | C6: The Units Sold and Unit Price columns contained missing numerical values.
C7: Copilot calculated the average value for each column and replaced the missing entries with the respective mean.
C8: This approach maintains numerical consistency and prevents bias caused by random value insertion.
A10: Suggested Values :-
A11: Units Sold | C11: Filled using column average
A12: Unit Price | C12: Filled using column average
A14: Formula Used :-=AVERAGE(range)

Sheet QUES4
A1: Ques 4 -: New Column: Total Revenue
A3: Copilot Prompt :- | C3: Add a new column named Total Revenue and calculate it using Units Sold and Unit Price.
A5: Solution :- | C5: A new column named Total Revenue was added in the Retail_Dataset sheet. Total Revenue was calculated by multiplying Units Sold with Unit Price for each order.
A7: Formula Used :- =H2*I2

Sheet QUES5
A1: Ques 5 - : | B1: Total Price for Order ID = ORD0123
A3: Copilot Prompt :- | C3: What is the total revenue for Order ID ORD0123?
A5: Solution :- | C5: The total revenue for Order ID ORD0123 was identified from the Total Revenue column in the Retail_Dataset sheet.
A7: Total Revenue :- | C7: 15849.3
A9: Formula Used :- =Units Sold * Unit Price

Sheet QUES6
A1: Region | B1: Average Profit
A2: East | B2: =AVERAGEIF(Retail_Dataset!B:B, A2, Retail_Dataset!L:L) -> 65823.338
A3: North | B3: =AVERAGEIF(Retail_Dataset!B:B, A3, Retail_Dataset!L:L) -> 65444.397
A4: South | B4: =AVERAGEIF(Retail_Dataset!B:B, A4, Retail_Dataset!L:L) -> 52497.308
A5: West | B5: =AVERAGEIF(Retail_Dataset!B:B, A5, Retail_Dataset!L:L) -> 58884.286
A7: Ques -6 :- | B7: Summary Chart of Average Profit by Region.
A9: Copilot Prompt: | C9: Create a bar chart showing the average profit for each region.
A11: Solution -: | C11: Copilot calculated the average profit for each region using
C12: the Profit column and grouped the results by Region.
C13: A bar chart was generated to visually compare the average
C14: profit across different regions,
C15: making it easier to identify high- and low-performing regions.
A17: Formula used -: =AVERAGE(range)
A21: This chart shows the average profit generated across different regions.

Sheet QUES7
A1: Ques -7 -: Create a pivot table summarizing total sales by category and region.
A3: Sum of Total Revenue | B3: Column Labels
A4: Row Labels | B4: East | C4: North | D4: South | E4: West | F4: Grand Total
A5: Beverages | B5: 888153.51 | C5: 985999.04 | D5: 1145872.8 | E5: 1833506.5 | F5: 4853531.9
A6: Clothing | B6: 1459067.6 | C6: 736434.66 | D6: 496502.89 | E6: 961692.7 | F6: 3653697.8
A7: Electronics | B7: 944943.52 | C7: 1099245.5 | D7: 892679.01 | E7: 1286638.7 | F7: 4223506.8
A8: Food | B8: 833638.81 | C8: 1498374.6 | D8: 567878.66 | E8: 792956.55 | F8: 3692848.6
A9: Furniture | B9: 1659890.5 | C9: 867213.15 | D9: 832820.25 | E9: 926634.58 | F9: 4286558.5
A10: Grand Total | B10: 5785693.9 | C10: 5187267 | D10: 3935753.7 | E10: 5801429.1 | F10: 20710144
A12: Copilot Prompt: | B12: Create a pivot table showing the sum of total revenue by category in rows and region in columns.
A14: Solution - : | B14: A pivot table was created using Category as rows and Region as columns, with Total Revenue aggregated as the sum.
B15: This table provides a clear comparison of sales performance across different categories and regions.

Sheet QUES8
A1: Ques 8 -: | B1: Build a Dashboard Combining Key KPIs and Charts.
A3: Copilot Prompt - : | C3: Use the dataset to build a dashboard that displays key KPIs including total revenue, total units sold, total profit,
C4: and average profit. Also include charts for revenue by category, profit by region, and monthly revenue trends.
A6: Solution - : | C6: Copilot created a dashboard by summarizing key performance indicators (KPIs) from the dataset.
C7: The dashboard includes total revenue, total units sold, total profit, and average profit displayed prominently at the top.
C8: Visual charts were added to represent revenue by category, average profit by region, and monthly
C9: revenue trends, providing a clear and interactive overview of business performance.
A12: KPI's Used -: | C12: Total Revenue → =SUM(Total_Revenue)
C14: Total Units Sold → =SUM(Units_Sold)
C16: Total Profit → =SUM(Profit)
C18: Average Profit → =AVERAGE(Profit)
A21: Charts Included :- | C21: Revenue by Category (Column Chart)
C23: Average Profit by Region (Bar Chart)
C25: Monthly Revenue Trend (Line Chart)
A27: Purpose of Dashboard - : | D27: This dashboard provides a consolidated view of sales and profit performance, helping stakeholders quickly analyze trends,
D28: compare regions and categories, and make data-driven decisions.

Sheet QUES9
A1: Ques - 9 | B1: Identify Top Performing Category by Total Revenue.
A3: Copilot Prompt -: | C3: Identify the product category that generates the highest total revenue using the dataset.
A5: Solution -: | C5: Copilot analyzed the dataset and calculated the total revenue for each product category by summing the Total Revenue values.
C6: After comparing all categories, Clothing emerged as the top-performing category with the highest total revenue.
C7: This indicates that the Clothing category contributes the most to overall sales performance.
A9: Metric Used :- | C9: Total Revenue = SUM(Total Revenue)
A11: Method Applied :- | C11: Group data by Category
C13: Aggregate Total Revenue for each category
C15: Compare totals to identify the highest-performing category
A17: Insight :- | C17: The Clothing category drives the maximum revenue, suggesting strong customer demand and sales performance in this segment.
